<?xml version ="1.0"?>
<robot name="mon_premier_robot">
    <link name="base_link">
        <visual>
            <geometry>
                <cylinder radius="0.25" length="0.1" />
            </geometry>
        </visual>
    </link>


    <link name="right_wheel">
        <visual>
            <geometry>
                <cylinder radius="0.05" length="0.03" />
            </geometry>
            <origin rpy="1.57075 0.0 0.0"/>
        </visual>
    </link>

    <joint name="right_wheel_joint" type="continuous">
        <parent link="base_link"/>
        <child link="right_wheel"/>
        <origin xyz="0.1 -0.2 -0.025"/>
        <axis xyz="0.0 1.0 0.0"/>
    </joint>    

    <link name="left_wheel">
        <visual>
            <geometry>
                <cylinder radius="0.05" length="0.03" />
            </geometry>
            <origin rpy="1.57075 0.0 0.0"/>
        </visual>
    </link>

    <joint name="left_wheel_joint" type="continuous">
        <parent link="base_link"/>
        <child link="left_wheel"/>
        <origin xyz="0.1 0.2 -0.025"/>
        <axis xyz="0.0 1.0 0.0"/>
    </joint>    



    <!-- TACHE 05 : AJOUTER LA ROUE FOLLE
    Cette roue est cylindre. Elle fait 5cm de diametre et 2cm d'epaisseur
    Elle est positionnee dans le plan XZ central du robot a 20cm sur l'arriere
    Elle est positionnee en hauteur de maniere a ce que le corps du robot soit
    parallele au sol
    -->


    <!-- FIN DE LA TACHE 05-->

</robot>