<?xml version ="1.0"?>
<robot name="mon_premier_robot">

<!-- TACHE 06 : CREER UN MATERIAU NOIR-->

<!-- FIN DE LA TACHE -->

    <link name="base_link">
        <visual>
            <geometry>
<!-- TACHE 06 : REMPLACER LE MODELE VISUEL du BASE_LINK pour un VOLUME MAILLE-->
                <cylinder radius="0.25" length="0.1" />
<!-- FIN DE LA TACHE -->
            </geometry>
        </visual>
    </link>


    <link name="right_wheel">
        <visual>
            <geometry>
                <cylinder radius="0.05" length="0.03" />
            </geometry>
            <origin rpy="1.57075 0.0 0.0"/>
<!-- TACHE 06 : UTILISER LE MATERIAU NOIR SUR CETTE ROUE-->

<!-- FIN DE LA TACHE -->
        </visual>
    </link>

    <joint name="right_wheel_joint" type="continuous">
        <parent link="base_link"/>
        <child link="right_wheel"/>
        <origin xyz="0.1 -0.2 -0.025"/>
        <axis xyz="0.0 1.0 0.0"/>
    </joint>    

    <link name="left_wheel">
        <visual>
            <geometry>
                <cylinder radius="0.05" length="0.03" />
            </geometry>
            <origin rpy="1.57075 0.0 0.0"/>
<!-- TACHE 06 : UTILISER LE MATERIAU NOIR SUR CETTE ROUE-->

<!-- FIN DE LA TACHE -->
        </visual>
    </link>

    <joint name="left_wheel_joint" type="continuous">
        <parent link="base_link"/>
        <child link="left_wheel"/>
        <origin xyz="0.1 0.2 -0.025"/>
        <axis xyz="0.0 1.0 0.0"/>
    </joint>    

    <link name="crazy_wheel_support"/>

    <joint name="crazy_wheel_support_joint" type="continuous">
        <parent link="base_link"/>
        <child link="crazy_wheel_support"/>
        <origin xyz="-0.2 0.0 -0.05"/>
        <axis xyz="0.0 0.0 1.0"/>
    </joint>    

    <link name="crazy_wheel">
        <visual>
            <geometry>
                <cylinder radius="0.025" length="0.02" />
            </geometry>
            <origin rpy="1.57075 0.0 0.0"/>
<!-- TACHE 06 : UTILISER LE MATERIAU NOIR SUR CETTE ROUE-->

<!-- FIN DE LA TACHE -->
        </visual>
    </link>

    <joint name="crazy_wheel_joint" type="continuous">
        <parent link="crazy_wheel_support"/>
        <child link="crazy_wheel"/>
        <origin xyz="0.0 0.0 0.0"/>
        <axis xyz="0.0 1.0 0.0"/>
    </joint>    

</robot>